Traceback (most recent call last):
  File "/Users/tompkins/Library/Python/3.9/lib/python/site-packages/jupyter_cache/executors/utils.py", line 58, in single_nb_execution
    executenb(
  File "/Users/tompkins/Library/Python/3.9/lib/python/site-packages/nbclient/client.py", line 1265, in execute
    return NotebookClient(nb=nb, resources=resources, km=km, **kwargs).execute()
  File "/Users/tompkins/Library/Python/3.9/lib/python/site-packages/jupyter_core/utils/__init__.py", line 166, in wrapped
    return loop.run_until_complete(inner)
  File "/Library/Developer/CommandLineTools/Library/Frameworks/Python3.framework/Versions/3.9/lib/python3.9/asyncio/base_events.py", line 642, in run_until_complete
    return future.result()
  File "/Users/tompkins/Library/Python/3.9/lib/python/site-packages/nbclient/client.py", line 703, in async_execute
    await self.async_execute_cell(
  File "/Users/tompkins/Library/Python/3.9/lib/python/site-packages/nbclient/client.py", line 1021, in async_execute_cell
    await self._check_raise_for_error(cell, cell_index, exec_reply)
  File "/Users/tompkins/Library/Python/3.9/lib/python/site-packages/nbclient/client.py", line 915, in _check_raise_for_error
    raise CellExecutionError.from_cell_and_msg(cell, exec_reply_content)
nbclient.exceptions.CellExecutionError: An error occurred while executing the following cell:
------------------


import cdsapi
c = cdsapi.Client()

from netCDF4 import Dataset,num2date
import matplotlib.pyplot as plt
import cartopy.crs as ccrs
import cartopy.feature as cfea
import cartopy.util as cutil
import matplotlib as mplt
import numpy as np
from mpl_toolkits.axes_grid1 import make_axes_locatable
from cdo import Cdo
import os 
from matplotlib.colors import LinearSegmentedColormap


cdo=Cdo()
scr="/Users/tompkins/Downloads/"
------------------

[0;31m---------------------------------------------------------------------------[0m
[0;31mValueError[0m                                Traceback (most recent call last)
Cell [0;32mIn[1], line 4[0m
[1;32m      1[0m [38;5;28;01mimport[39;00m [38;5;21;01mcdsapi[39;00m
[1;32m      2[0m c [38;5;241m=[39m cdsapi[38;5;241m.[39mClient()
[0;32m----> 4[0m [38;5;28;01mfrom[39;00m [38;5;21;01mnetCDF4[39;00m [38;5;28;01mimport[39;00m Dataset,num2date
[1;32m      5[0m [38;5;28;01mimport[39;00m [38;5;21;01mmatplotlib[39;00m[38;5;21;01m.[39;00m[38;5;21;01mpyplot[39;00m [38;5;28;01mas[39;00m [38;5;21;01mplt[39;00m
[1;32m      6[0m [38;5;28;01mimport[39;00m [38;5;21;01mcartopy[39;00m[38;5;21;01m.[39;00m[38;5;21;01mcrs[39;00m [38;5;28;01mas[39;00m [38;5;21;01mccrs[39;00m

File [0;32m~/Library/Python/3.9/lib/python/site-packages/netCDF4/__init__.py:3[0m
[1;32m      1[0m [38;5;66;03m# init for netCDF4. package[39;00m
[1;32m      2[0m [38;5;66;03m# Docstring comes from extension module _netCDF4.[39;00m
[0;32m----> 3[0m [38;5;28;01mfrom[39;00m [38;5;21;01m.[39;00m[38;5;21;01m_netCDF4[39;00m [38;5;28;01mimport[39;00m [38;5;241m*[39m
[1;32m      4[0m [38;5;66;03m# Need explicit imports for names beginning with underscores[39;00m
[1;32m      5[0m [38;5;28;01mfrom[39;00m [38;5;21;01m.[39;00m[38;5;21;01m_netCDF4[39;00m [38;5;28;01mimport[39;00m [38;5;18m__doc__[39m

File [0;32msrc/netCDF4/_netCDF4.pyx:1[0m, in [0;36minit netCDF4._netCDF4[0;34m()[0m

[0;31mValueError[0m: numpy.dtype size changed, may indicate binary incompatibility. Expected 96 from C header, got 88 from PyObject
ValueError: numpy.dtype size changed, may indicate binary incompatibility. Expected 96 from C header, got 88 from PyObject

