Traceback (most recent call last):
  File "/Users/tompkins/miniconda3/envs/climlabfix/lib/python3.10/site-packages/nbclient/client.py", line 778, in _async_poll_for_reply
    msg = await ensure_async(self.kc.shell_channel.get_msg(timeout=new_timeout))
  File "/Users/tompkins/miniconda3/envs/climlabfix/lib/python3.10/site-packages/jupyter_core/utils/__init__.py", line 189, in ensure_async
    result = await obj
  File "/Users/tompkins/miniconda3/envs/climlabfix/lib/python3.10/site-packages/jupyter_client/channels.py", line 315, in get_msg
    raise Empty
_queue.Empty

During handling of the above exception, another exception occurred:

Traceback (most recent call last):
  File "/Users/tompkins/miniconda3/envs/climlabfix/lib/python3.10/site-packages/jupyter_cache/executors/utils.py", line 58, in single_nb_execution
    executenb(
  File "/Users/tompkins/miniconda3/envs/climlabfix/lib/python3.10/site-packages/nbclient/client.py", line 1305, in execute
    return NotebookClient(nb=nb, resources=resources, km=km, **kwargs).execute()
  File "/Users/tompkins/miniconda3/envs/climlabfix/lib/python3.10/site-packages/jupyter_core/utils/__init__.py", line 173, in wrapped
    return loop.run_until_complete(inner)
  File "/Users/tompkins/miniconda3/envs/climlabfix/lib/python3.10/asyncio/base_events.py", line 649, in run_until_complete
    return future.result()
  File "/Users/tompkins/miniconda3/envs/climlabfix/lib/python3.10/site-packages/nbclient/client.py", line 705, in async_execute
    await self.async_execute_cell(
  File "/Users/tompkins/miniconda3/envs/climlabfix/lib/python3.10/site-packages/nbclient/client.py", line 1001, in async_execute_cell
    exec_reply = await self.task_poll_for_reply
  File "/Users/tompkins/miniconda3/envs/climlabfix/lib/python3.10/site-packages/nbclient/client.py", line 802, in _async_poll_for_reply
    error_on_timeout_execute_reply = await self._async_handle_timeout(timeout, cell)
  File "/Users/tompkins/miniconda3/envs/climlabfix/lib/python3.10/site-packages/nbclient/client.py", line 852, in _async_handle_timeout
    raise CellTimeoutError.error_from_timeout_and_cell(
nbclient.exceptions.CellTimeoutError: A cell timed out while it was being executed, after 30 seconds.
The message was: Cell execution timed out.
Here is a preview of the cell contents:
-------------------
['### cut and paste model list into a text file, read to list with readlines', '### and then convert to usable list like this:', '### t=list(filter(None,[l.split(" (",1)[0].replace(\'\\n\',\'\').replace(\'-\',\'_\') for l in lns]))', '', "# let's try it out "]
...
['# this is the experiment: (SSP+RCP)', '# e.g. ssp5_8_5 is SSP5 with RCP8.5 (Wm-2 end of century forcing )', "exp='ssp5_8_5'", '', 'ofile=get_var(model,var,exp)']
-------------------

